2024-05-13 19:42:34,376 FILE: creds.py IN: create_new_token MESSAGE: Ошибка получения iam_token: HTTPConnectionPool(host='169.254.169.254', port=80): Max retries exceeded with url: /computeMetadata/v1/instance/service-accounts/default/token (Caused by ConnectTimeoutError(<urllib3.connection.HTTPConnection object at 0x000002BD13319F40>, 'Connection to 169.254.169.254 timed out. (connect timeout=None)'))
2024-05-13 19:42:55,447 FILE: creds.py IN: create_new_token MESSAGE: Ошибка получения iam_token: HTTPConnectionPool(host='169.254.169.254', port=80): Max retries exceeded with url: /computeMetadata/v1/instance/service-accounts/default/token (Caused by ConnectTimeoutError(<urllib3.connection.HTTPConnection object at 0x000002BD134F6720>, 'Connection to 169.254.169.254 timed out. (connect timeout=None)'))
2024-05-13 19:43:16,493 FILE: creds.py IN: create_new_token MESSAGE: Ошибка получения iam_token: HTTPConnectionPool(host='169.254.169.254', port=80): Max retries exceeded with url: /computeMetadata/v1/instance/service-accounts/default/token (Caused by ConnectTimeoutError(<urllib3.connection.HTTPConnection object at 0x000002BD134F6FF0>, 'Connection to 169.254.169.254 timed out. (connect timeout=None)'))
2024-05-13 19:43:16,495 FILE: db.py IN: create_database MESSAGE: DATABASE: База данных создана
